[2024-06-28T09:15:12.901+0000] {local_task_job_runner.py:120} INFO - ::group::Pre task execution logs
[2024-06-28T09:15:12.920+0000] {taskinstance.py:2076} INFO - Dependencies all met for dep_context=non-requeueable deps ti=<TaskInstance: weather_data_pipeline.predict_weather manual__2024-06-28T09:15:00.759910+00:00 [queued]>
[2024-06-28T09:15:12.930+0000] {taskinstance.py:2076} INFO - Dependencies all met for dep_context=requeueable deps ti=<TaskInstance: weather_data_pipeline.predict_weather manual__2024-06-28T09:15:00.759910+00:00 [queued]>
[2024-06-28T09:15:12.931+0000] {taskinstance.py:2306} INFO - Starting attempt 1 of 2
[2024-06-28T09:15:12.944+0000] {taskinstance.py:2330} INFO - Executing <Task(PythonOperator): predict_weather> on 2024-06-28 09:15:00.759910+00:00
[2024-06-28T09:15:12.950+0000] {warnings.py:112} WARNING - /home/***/.local/lib/python3.12/site-packages/***/task/task_runner/standard_task_runner.py:61: DeprecationWarning: This process (pid=110) is multi-threaded, use of fork() may lead to deadlocks in the child.
  pid = os.fork()

[2024-06-28T09:15:12.951+0000] {standard_task_runner.py:90} INFO - Running: ['***', 'tasks', 'run', 'weather_data_pipeline', 'predict_weather', 'manual__2024-06-28T09:15:00.759910+00:00', '--job-id', '63', '--raw', '--subdir', 'DAGS_FOLDER/weather_dag.py', '--cfg-path', '/tmp/tmpe1ri9uyx']
[2024-06-28T09:15:12.952+0000] {standard_task_runner.py:63} INFO - Started process 124 to run task
[2024-06-28T09:15:12.952+0000] {standard_task_runner.py:91} INFO - Job 63: Subtask predict_weather
[2024-06-28T09:15:12.994+0000] {task_command.py:426} INFO - Running <TaskInstance: weather_data_pipeline.predict_weather manual__2024-06-28T09:15:00.759910+00:00 [running]> on host 72af1dab7ef8
[2024-06-28T09:15:13.090+0000] {taskinstance.py:2648} INFO - Exporting env vars: AIRFLOW_CTX_DAG_OWNER='***' AIRFLOW_CTX_DAG_ID='weather_data_pipeline' AIRFLOW_CTX_TASK_ID='predict_weather' AIRFLOW_CTX_EXECUTION_DATE='2024-06-28T09:15:00.759910+00:00' AIRFLOW_CTX_TRY_NUMBER='1' AIRFLOW_CTX_DAG_RUN_ID='manual__2024-06-28T09:15:00.759910+00:00'
[2024-06-28T09:15:13.092+0000] {taskinstance.py:430} INFO - ::endgroup::
[2024-06-28T09:15:13.096+0000] {taskinstance.py:441} INFO - ::group::Post task execution logs
[2024-06-28T09:15:13.097+0000] {taskinstance.py:2905} ERROR - Task failed with exception
Traceback (most recent call last):
  File "/home/airflow/.local/lib/python3.12/site-packages/airflow/models/taskinstance.py", line 465, in _execute_task
    result = _execute_callable(context=context, **execute_callable_kwargs)
             ^^^^^^^^^^^^^^^^^^^^^^^^^^^^^^^^^^^^^^^^^^^^^^^^^^^^^^^^^^^^^
  File "/home/airflow/.local/lib/python3.12/site-packages/airflow/models/taskinstance.py", line 432, in _execute_callable
    return execute_callable(context=context, **execute_callable_kwargs)
           ^^^^^^^^^^^^^^^^^^^^^^^^^^^^^^^^^^^^^^^^^^^^^^^^^^^^^^^^^^^^
  File "/home/airflow/.local/lib/python3.12/site-packages/airflow/models/baseoperator.py", line 401, in wrapper
    return func(self, *args, **kwargs)
           ^^^^^^^^^^^^^^^^^^^^^^^^^^^
  File "/home/airflow/.local/lib/python3.12/site-packages/airflow/operators/python.py", line 235, in execute
    return_value = self.execute_callable()
                   ^^^^^^^^^^^^^^^^^^^^^^^
  File "/home/airflow/.local/lib/python3.12/site-packages/airflow/operators/python.py", line 252, in execute_callable
    return self.python_callable(*self.op_args, **self.op_kwargs)
           ^^^^^^^^^^^^^^^^^^^^^^^^^^^^^^^^^^^^^^^^^^^^^^^^^^^^^
  File "/opt/airflow/scripts/predict.py", line 7, in predict_weather
    data = pd.read_csv(save_path)
           ^^^^^^^^^^^^^^^^^^^^^^
  File "/home/airflow/.local/lib/python3.12/site-packages/pandas/io/parsers/readers.py", line 948, in read_csv
    return _read(filepath_or_buffer, kwds)
           ^^^^^^^^^^^^^^^^^^^^^^^^^^^^^^^
  File "/home/airflow/.local/lib/python3.12/site-packages/pandas/io/parsers/readers.py", line 611, in _read
    parser = TextFileReader(filepath_or_buffer, **kwds)
             ^^^^^^^^^^^^^^^^^^^^^^^^^^^^^^^^^^^^^^^^^^
  File "/home/airflow/.local/lib/python3.12/site-packages/pandas/io/parsers/readers.py", line 1448, in __init__
    self._engine = self._make_engine(f, self.engine)
                   ^^^^^^^^^^^^^^^^^^^^^^^^^^^^^^^^^
  File "/home/airflow/.local/lib/python3.12/site-packages/pandas/io/parsers/readers.py", line 1705, in _make_engine
    self.handles = get_handle(
                   ^^^^^^^^^^^
  File "/home/airflow/.local/lib/python3.12/site-packages/pandas/io/common.py", line 863, in get_handle
    handle = open(
             ^^^^^
FileNotFoundError: [Errno 2] No such file or directory: './new_data.csv'
[2024-06-28T09:15:13.111+0000] {taskinstance.py:1206} INFO - Marking task as UP_FOR_RETRY. dag_id=weather_data_pipeline, task_id=predict_weather, run_id=manual__2024-06-28T09:15:00.759910+00:00, execution_date=20240628T091500, start_date=20240628T091512, end_date=20240628T091513
[2024-06-28T09:15:13.124+0000] {standard_task_runner.py:110} ERROR - Failed to execute job 63 for task predict_weather ([Errno 2] No such file or directory: './new_data.csv'; 124)
[2024-06-28T09:15:13.167+0000] {local_task_job_runner.py:240} INFO - Task exited with return code 1
[2024-06-28T09:15:13.197+0000] {taskinstance.py:3503} INFO - 0 downstream tasks scheduled from follow-on schedule check
[2024-06-28T09:15:13.202+0000] {local_task_job_runner.py:222} INFO - ::endgroup::
