[2024-06-28T04:02:15.025+0000] {local_task_job_runner.py:120} INFO - ::group::Pre task execution logs
[2024-06-28T04:02:15.096+0000] {taskinstance.py:2076} INFO - Dependencies all met for dep_context=non-requeueable deps ti=<TaskInstance: weather_data_pipeline.predict_weather manual__2024-06-28T03:56:50.826976+00:00 [queued]>
[2024-06-28T04:02:15.125+0000] {taskinstance.py:2076} INFO - Dependencies all met for dep_context=requeueable deps ti=<TaskInstance: weather_data_pipeline.predict_weather manual__2024-06-28T03:56:50.826976+00:00 [queued]>
[2024-06-28T04:02:15.126+0000] {taskinstance.py:2306} INFO - Starting attempt 2 of 2
[2024-06-28T04:02:15.221+0000] {taskinstance.py:2330} INFO - Executing <Task(PythonOperator): predict_weather> on 2024-06-28 03:56:50.826976+00:00
[2024-06-28T04:02:15.234+0000] {warnings.py:112} WARNING - /home/***/.local/lib/python3.12/site-packages/***/task/task_runner/standard_task_runner.py:61: DeprecationWarning: This process (pid=254) is multi-threaded, use of fork() may lead to deadlocks in the child.
  pid = os.fork()

[2024-06-28T04:02:15.237+0000] {standard_task_runner.py:63} INFO - Started process 263 to run task
[2024-06-28T04:02:15.245+0000] {standard_task_runner.py:90} INFO - Running: ['***', 'tasks', 'run', 'weather_data_pipeline', 'predict_weather', 'manual__2024-06-28T03:56:50.826976+00:00', '--job-id', '24', '--raw', '--subdir', 'DAGS_FOLDER/weather_dag.py', '--cfg-path', '/tmp/tmpdyr139e_']
[2024-06-28T04:02:15.248+0000] {standard_task_runner.py:91} INFO - Job 24: Subtask predict_weather
[2024-06-28T04:02:15.438+0000] {task_command.py:426} INFO - Running <TaskInstance: weather_data_pipeline.predict_weather manual__2024-06-28T03:56:50.826976+00:00 [running]> on host 2efad63007cb
[2024-06-28T04:02:15.786+0000] {taskinstance.py:2648} INFO - Exporting env vars: AIRFLOW_CTX_DAG_OWNER='***' AIRFLOW_CTX_DAG_ID='weather_data_pipeline' AIRFLOW_CTX_TASK_ID='predict_weather' AIRFLOW_CTX_EXECUTION_DATE='2024-06-28T03:56:50.826976+00:00' AIRFLOW_CTX_TRY_NUMBER='2' AIRFLOW_CTX_DAG_RUN_ID='manual__2024-06-28T03:56:50.826976+00:00'
[2024-06-28T04:02:15.788+0000] {taskinstance.py:430} INFO - ::endgroup::
[2024-06-28T04:02:18.411+0000] {taskinstance.py:441} INFO - ::group::Post task execution logs
[2024-06-28T04:02:18.412+0000] {taskinstance.py:2905} ERROR - Task failed with exception
Traceback (most recent call last):
  File "/home/airflow/.local/lib/python3.12/site-packages/airflow/models/taskinstance.py", line 465, in _execute_task
    result = _execute_callable(context=context, **execute_callable_kwargs)
             ^^^^^^^^^^^^^^^^^^^^^^^^^^^^^^^^^^^^^^^^^^^^^^^^^^^^^^^^^^^^^
  File "/home/airflow/.local/lib/python3.12/site-packages/airflow/models/taskinstance.py", line 432, in _execute_callable
    return execute_callable(context=context, **execute_callable_kwargs)
           ^^^^^^^^^^^^^^^^^^^^^^^^^^^^^^^^^^^^^^^^^^^^^^^^^^^^^^^^^^^^
  File "/home/airflow/.local/lib/python3.12/site-packages/airflow/models/baseoperator.py", line 401, in wrapper
    return func(self, *args, **kwargs)
           ^^^^^^^^^^^^^^^^^^^^^^^^^^^
  File "/home/airflow/.local/lib/python3.12/site-packages/airflow/operators/python.py", line 235, in execute
    return_value = self.execute_callable()
                   ^^^^^^^^^^^^^^^^^^^^^^^
  File "/home/airflow/.local/lib/python3.12/site-packages/airflow/operators/python.py", line 252, in execute_callable
    return self.python_callable(*self.op_args, **self.op_kwargs)
           ^^^^^^^^^^^^^^^^^^^^^^^^^^^^^^^^^^^^^^^^^^^^^^^^^^^^^
  File "/opt/airflow/scripts/predict.py", line 18, in predict_weather
    data['predicted_temperature_2m'] = model.predict(features)
                                       ^^^^^^^^^^^^^^^^^^^^^^^
  File "/home/airflow/.local/lib/python3.12/site-packages/sklearn/linear_model/_base.py", line 306, in predict
    return self._decision_function(X)
           ^^^^^^^^^^^^^^^^^^^^^^^^^^
  File "/home/airflow/.local/lib/python3.12/site-packages/sklearn/linear_model/_base.py", line 285, in _decision_function
    X = self._validate_data(X, accept_sparse=["csr", "csc", "coo"], reset=False)
        ^^^^^^^^^^^^^^^^^^^^^^^^^^^^^^^^^^^^^^^^^^^^^^^^^^^^^^^^^^^^^^^^^^^^^^^^
  File "/home/airflow/.local/lib/python3.12/site-packages/sklearn/base.py", line 608, in _validate_data
    self._check_feature_names(X, reset=reset)
  File "/home/airflow/.local/lib/python3.12/site-packages/sklearn/base.py", line 535, in _check_feature_names
    raise ValueError(message)
ValueError: The feature names should match those that were passed during fit.
Feature names unseen at fit time:
- date
Feature names seen at fit time, yet now missing:
- day
- hour
- month
- year

[2024-06-28T04:02:18.444+0000] {taskinstance.py:1206} INFO - Marking task as FAILED. dag_id=weather_data_pipeline, task_id=predict_weather, run_id=manual__2024-06-28T03:56:50.826976+00:00, execution_date=20240628T035650, start_date=20240628T040215, end_date=20240628T040218
[2024-06-28T04:02:18.509+0000] {standard_task_runner.py:110} ERROR - Failed to execute job 24 for task predict_weather (The feature names should match those that were passed during fit.
Feature names unseen at fit time:
- date
Feature names seen at fit time, yet now missing:
- day
- hour
- month
- year
; 263)
[2024-06-28T04:02:18.602+0000] {local_task_job_runner.py:240} INFO - Task exited with return code 1
[2024-06-28T04:02:18.677+0000] {taskinstance.py:3503} INFO - 0 downstream tasks scheduled from follow-on schedule check
[2024-06-28T04:02:18.696+0000] {local_task_job_runner.py:222} INFO - ::endgroup::
