[2024-06-28T03:23:27.898+0000] {local_task_job_runner.py:120} INFO - ::group::Pre task execution logs
[2024-06-28T03:23:28.053+0000] {taskinstance.py:2076} INFO - Dependencies all met for dep_context=non-requeueable deps ti=<TaskInstance: weather_data_pipeline.predict_weather scheduled__2024-06-27T00:00:00+00:00 [queued]>
[2024-06-28T03:23:28.091+0000] {taskinstance.py:2076} INFO - Dependencies all met for dep_context=requeueable deps ti=<TaskInstance: weather_data_pipeline.predict_weather scheduled__2024-06-27T00:00:00+00:00 [queued]>
[2024-06-28T03:23:28.091+0000] {taskinstance.py:2306} INFO - Starting attempt 1 of 2
[2024-06-28T03:23:28.161+0000] {taskinstance.py:2330} INFO - Executing <Task(PythonOperator): predict_weather> on 2024-06-27 00:00:00+00:00
[2024-06-28T03:23:28.191+0000] {warnings.py:112} WARNING - /home/***/.local/lib/python3.12/site-packages/***/task/task_runner/standard_task_runner.py:61: DeprecationWarning: This process (pid=383) is multi-threaded, use of fork() may lead to deadlocks in the child.
  pid = os.fork()

[2024-06-28T03:23:28.198+0000] {standard_task_runner.py:63} INFO - Started process 395 to run task
[2024-06-28T03:23:28.194+0000] {standard_task_runner.py:90} INFO - Running: ['***', 'tasks', 'run', 'weather_data_pipeline', 'predict_weather', 'scheduled__2024-06-27T00:00:00+00:00', '--job-id', '13', '--raw', '--subdir', 'DAGS_FOLDER/weather_dag.py', '--cfg-path', '/tmp/tmpetiqlebg']
[2024-06-28T03:23:28.206+0000] {standard_task_runner.py:91} INFO - Job 13: Subtask predict_weather
[2024-06-28T03:23:28.427+0000] {task_command.py:426} INFO - Running <TaskInstance: weather_data_pipeline.predict_weather scheduled__2024-06-27T00:00:00+00:00 [running]> on host 29974a26e5b4
[2024-06-28T03:23:28.790+0000] {taskinstance.py:2648} INFO - Exporting env vars: AIRFLOW_CTX_DAG_OWNER='***' AIRFLOW_CTX_DAG_ID='weather_data_pipeline' AIRFLOW_CTX_TASK_ID='predict_weather' AIRFLOW_CTX_EXECUTION_DATE='2024-06-27T00:00:00+00:00' AIRFLOW_CTX_TRY_NUMBER='1' AIRFLOW_CTX_DAG_RUN_ID='scheduled__2024-06-27T00:00:00+00:00'
[2024-06-28T03:23:28.791+0000] {taskinstance.py:430} INFO - ::endgroup::
[2024-06-28T03:23:31.133+0000] {taskinstance.py:441} INFO - ::group::Post task execution logs
[2024-06-28T03:23:31.134+0000] {taskinstance.py:2905} ERROR - Task failed with exception
Traceback (most recent call last):
  File "/home/airflow/.local/lib/python3.12/site-packages/airflow/models/taskinstance.py", line 465, in _execute_task
    result = _execute_callable(context=context, **execute_callable_kwargs)
             ^^^^^^^^^^^^^^^^^^^^^^^^^^^^^^^^^^^^^^^^^^^^^^^^^^^^^^^^^^^^^
  File "/home/airflow/.local/lib/python3.12/site-packages/airflow/models/taskinstance.py", line 432, in _execute_callable
    return execute_callable(context=context, **execute_callable_kwargs)
           ^^^^^^^^^^^^^^^^^^^^^^^^^^^^^^^^^^^^^^^^^^^^^^^^^^^^^^^^^^^^
  File "/home/airflow/.local/lib/python3.12/site-packages/airflow/models/baseoperator.py", line 401, in wrapper
    return func(self, *args, **kwargs)
           ^^^^^^^^^^^^^^^^^^^^^^^^^^^
  File "/home/airflow/.local/lib/python3.12/site-packages/airflow/operators/python.py", line 235, in execute
    return_value = self.execute_callable()
                   ^^^^^^^^^^^^^^^^^^^^^^^
  File "/home/airflow/.local/lib/python3.12/site-packages/airflow/operators/python.py", line 252, in execute_callable
    return self.python_callable(*self.op_args, **self.op_kwargs)
           ^^^^^^^^^^^^^^^^^^^^^^^^^^^^^^^^^^^^^^^^^^^^^^^^^^^^^
  File "/opt/airflow/scripts/predict.py", line 18, in predict_weather
    data['predicted_temperature_2m'] = model.predict(features)
                                       ^^^^^^^^^^^^^^^^^^^^^^^
  File "/home/airflow/.local/lib/python3.12/site-packages/sklearn/linear_model/_base.py", line 306, in predict
    return self._decision_function(X)
           ^^^^^^^^^^^^^^^^^^^^^^^^^^
  File "/home/airflow/.local/lib/python3.12/site-packages/sklearn/linear_model/_base.py", line 285, in _decision_function
    X = self._validate_data(X, accept_sparse=["csr", "csc", "coo"], reset=False)
        ^^^^^^^^^^^^^^^^^^^^^^^^^^^^^^^^^^^^^^^^^^^^^^^^^^^^^^^^^^^^^^^^^^^^^^^^
  File "/home/airflow/.local/lib/python3.12/site-packages/sklearn/base.py", line 608, in _validate_data
    self._check_feature_names(X, reset=reset)
  File "/home/airflow/.local/lib/python3.12/site-packages/sklearn/base.py", line 535, in _check_feature_names
    raise ValueError(message)
ValueError: The feature names should match those that were passed during fit.
Feature names unseen at fit time:
- date
Feature names seen at fit time, yet now missing:
- day
- hour
- month
- year

[2024-06-28T03:23:31.151+0000] {taskinstance.py:1206} INFO - Marking task as UP_FOR_RETRY. dag_id=weather_data_pipeline, task_id=predict_weather, run_id=scheduled__2024-06-27T00:00:00+00:00, execution_date=20240627T000000, start_date=20240628T032328, end_date=20240628T032331
[2024-06-28T03:23:31.178+0000] {standard_task_runner.py:110} ERROR - Failed to execute job 13 for task predict_weather (The feature names should match those that were passed during fit.
Feature names unseen at fit time:
- date
Feature names seen at fit time, yet now missing:
- day
- hour
- month
- year
; 395)
[2024-06-28T03:23:31.229+0000] {local_task_job_runner.py:240} INFO - Task exited with return code 1
[2024-06-28T03:23:31.263+0000] {taskinstance.py:3503} INFO - 0 downstream tasks scheduled from follow-on schedule check
[2024-06-28T03:23:31.264+0000] {local_task_job_runner.py:222} INFO - ::endgroup::
[2024-06-28T03:25:14.478+0000] {local_task_job_runner.py:120} INFO - ::group::Pre task execution logs
[2024-06-28T03:25:14.667+0000] {taskinstance.py:2076} INFO - Dependencies all met for dep_context=non-requeueable deps ti=<TaskInstance: weather_data_pipeline.predict_weather scheduled__2024-06-27T00:00:00+00:00 [queued]>
[2024-06-28T03:25:14.718+0000] {taskinstance.py:2076} INFO - Dependencies all met for dep_context=requeueable deps ti=<TaskInstance: weather_data_pipeline.predict_weather scheduled__2024-06-27T00:00:00+00:00 [queued]>
[2024-06-28T03:25:14.719+0000] {taskinstance.py:2306} INFO - Starting attempt 1 of 2
[2024-06-28T03:25:14.902+0000] {taskinstance.py:2330} INFO - Executing <Task(PythonOperator): predict_weather> on 2024-06-27 00:00:00+00:00
[2024-06-28T03:25:14.951+0000] {standard_task_runner.py:90} INFO - Running: ['***', 'tasks', 'run', 'weather_data_pipeline', 'predict_weather', 'scheduled__2024-06-27T00:00:00+00:00', '--job-id', '15', '--raw', '--subdir', 'DAGS_FOLDER/weather_dag.py', '--cfg-path', '/tmp/tmphn28xaze']
[2024-06-28T03:25:14.966+0000] {standard_task_runner.py:91} INFO - Job 15: Subtask predict_weather
[2024-06-28T03:25:14.938+0000] {warnings.py:112} WARNING - /home/***/.local/lib/python3.12/site-packages/***/task/task_runner/standard_task_runner.py:61: DeprecationWarning: This process (pid=451) is multi-threaded, use of fork() may lead to deadlocks in the child.
  pid = os.fork()

[2024-06-28T03:25:14.969+0000] {standard_task_runner.py:63} INFO - Started process 460 to run task
[2024-06-28T03:25:15.218+0000] {task_command.py:426} INFO - Running <TaskInstance: weather_data_pipeline.predict_weather scheduled__2024-06-27T00:00:00+00:00 [running]> on host 29974a26e5b4
[2024-06-28T03:25:15.817+0000] {taskinstance.py:2648} INFO - Exporting env vars: AIRFLOW_CTX_DAG_OWNER='***' AIRFLOW_CTX_DAG_ID='weather_data_pipeline' AIRFLOW_CTX_TASK_ID='predict_weather' AIRFLOW_CTX_EXECUTION_DATE='2024-06-27T00:00:00+00:00' AIRFLOW_CTX_TRY_NUMBER='1' AIRFLOW_CTX_DAG_RUN_ID='scheduled__2024-06-27T00:00:00+00:00'
[2024-06-28T03:25:15.819+0000] {taskinstance.py:430} INFO - ::endgroup::
[2024-06-28T03:25:18.942+0000] {taskinstance.py:441} INFO - ::group::Post task execution logs
[2024-06-28T03:25:18.943+0000] {taskinstance.py:2905} ERROR - Task failed with exception
Traceback (most recent call last):
  File "/home/airflow/.local/lib/python3.12/site-packages/airflow/models/taskinstance.py", line 465, in _execute_task
    result = _execute_callable(context=context, **execute_callable_kwargs)
             ^^^^^^^^^^^^^^^^^^^^^^^^^^^^^^^^^^^^^^^^^^^^^^^^^^^^^^^^^^^^^
  File "/home/airflow/.local/lib/python3.12/site-packages/airflow/models/taskinstance.py", line 432, in _execute_callable
    return execute_callable(context=context, **execute_callable_kwargs)
           ^^^^^^^^^^^^^^^^^^^^^^^^^^^^^^^^^^^^^^^^^^^^^^^^^^^^^^^^^^^^
  File "/home/airflow/.local/lib/python3.12/site-packages/airflow/models/baseoperator.py", line 401, in wrapper
    return func(self, *args, **kwargs)
           ^^^^^^^^^^^^^^^^^^^^^^^^^^^
  File "/home/airflow/.local/lib/python3.12/site-packages/airflow/operators/python.py", line 235, in execute
    return_value = self.execute_callable()
                   ^^^^^^^^^^^^^^^^^^^^^^^
  File "/home/airflow/.local/lib/python3.12/site-packages/airflow/operators/python.py", line 252, in execute_callable
    return self.python_callable(*self.op_args, **self.op_kwargs)
           ^^^^^^^^^^^^^^^^^^^^^^^^^^^^^^^^^^^^^^^^^^^^^^^^^^^^^
  File "/opt/airflow/scripts/predict.py", line 18, in predict_weather
    data['predicted_temperature_2m'] = model.predict(features)
                                       ^^^^^^^^^^^^^^^^^^^^^^^
  File "/home/airflow/.local/lib/python3.12/site-packages/sklearn/linear_model/_base.py", line 306, in predict
    return self._decision_function(X)
           ^^^^^^^^^^^^^^^^^^^^^^^^^^
  File "/home/airflow/.local/lib/python3.12/site-packages/sklearn/linear_model/_base.py", line 285, in _decision_function
    X = self._validate_data(X, accept_sparse=["csr", "csc", "coo"], reset=False)
        ^^^^^^^^^^^^^^^^^^^^^^^^^^^^^^^^^^^^^^^^^^^^^^^^^^^^^^^^^^^^^^^^^^^^^^^^
  File "/home/airflow/.local/lib/python3.12/site-packages/sklearn/base.py", line 608, in _validate_data
    self._check_feature_names(X, reset=reset)
  File "/home/airflow/.local/lib/python3.12/site-packages/sklearn/base.py", line 535, in _check_feature_names
    raise ValueError(message)
ValueError: The feature names should match those that were passed during fit.
Feature names unseen at fit time:
- date
Feature names seen at fit time, yet now missing:
- day
- hour
- month
- year

[2024-06-28T03:25:18.977+0000] {taskinstance.py:1206} INFO - Marking task as UP_FOR_RETRY. dag_id=weather_data_pipeline, task_id=predict_weather, run_id=scheduled__2024-06-27T00:00:00+00:00, execution_date=20240627T000000, start_date=20240628T032514, end_date=20240628T032518
[2024-06-28T03:25:19.028+0000] {standard_task_runner.py:110} ERROR - Failed to execute job 15 for task predict_weather (The feature names should match those that were passed during fit.
Feature names unseen at fit time:
- date
Feature names seen at fit time, yet now missing:
- day
- hour
- month
- year
; 460)
[2024-06-28T03:25:19.106+0000] {local_task_job_runner.py:240} INFO - Task exited with return code 1
[2024-06-28T03:25:19.140+0000] {taskinstance.py:3503} INFO - 0 downstream tasks scheduled from follow-on schedule check
[2024-06-28T03:25:19.146+0000] {local_task_job_runner.py:222} INFO - ::endgroup::
[2024-06-28T03:30:04.708+0000] {local_task_job_runner.py:120} INFO - ::group::Pre task execution logs
[2024-06-28T03:30:04.743+0000] {taskinstance.py:2076} INFO - Dependencies all met for dep_context=non-requeueable deps ti=<TaskInstance: weather_data_pipeline.predict_weather scheduled__2024-06-27T00:00:00+00:00 [queued]>
[2024-06-28T03:30:04.756+0000] {taskinstance.py:2076} INFO - Dependencies all met for dep_context=requeueable deps ti=<TaskInstance: weather_data_pipeline.predict_weather scheduled__2024-06-27T00:00:00+00:00 [queued]>
[2024-06-28T03:30:04.756+0000] {taskinstance.py:2306} INFO - Starting attempt 1 of 2
[2024-06-28T03:30:04.803+0000] {taskinstance.py:2330} INFO - Executing <Task(PythonOperator): predict_weather> on 2024-06-27 00:00:00+00:00
[2024-06-28T03:30:04.829+0000] {standard_task_runner.py:90} INFO - Running: ['***', 'tasks', 'run', 'weather_data_pipeline', 'predict_weather', 'scheduled__2024-06-27T00:00:00+00:00', '--job-id', '18', '--raw', '--subdir', 'DAGS_FOLDER/weather_dag.py', '--cfg-path', '/tmp/tmpmy9qtpuu']
[2024-06-28T03:30:04.830+0000] {warnings.py:112} WARNING - /home/***/.local/lib/python3.12/site-packages/***/task/task_runner/standard_task_runner.py:61: DeprecationWarning: This process (pid=586) is multi-threaded, use of fork() may lead to deadlocks in the child.
  pid = os.fork()

[2024-06-28T03:30:04.832+0000] {standard_task_runner.py:91} INFO - Job 18: Subtask predict_weather
[2024-06-28T03:30:04.832+0000] {standard_task_runner.py:63} INFO - Started process 588 to run task
[2024-06-28T03:30:04.924+0000] {task_command.py:426} INFO - Running <TaskInstance: weather_data_pipeline.predict_weather scheduled__2024-06-27T00:00:00+00:00 [running]> on host 29974a26e5b4
[2024-06-28T03:30:05.095+0000] {taskinstance.py:2648} INFO - Exporting env vars: AIRFLOW_CTX_DAG_OWNER='***' AIRFLOW_CTX_DAG_ID='weather_data_pipeline' AIRFLOW_CTX_TASK_ID='predict_weather' AIRFLOW_CTX_EXECUTION_DATE='2024-06-27T00:00:00+00:00' AIRFLOW_CTX_TRY_NUMBER='1' AIRFLOW_CTX_DAG_RUN_ID='scheduled__2024-06-27T00:00:00+00:00'
[2024-06-28T03:30:05.097+0000] {taskinstance.py:430} INFO - ::endgroup::
[2024-06-28T03:30:06.463+0000] {taskinstance.py:441} INFO - ::group::Post task execution logs
[2024-06-28T03:30:06.464+0000] {taskinstance.py:2905} ERROR - Task failed with exception
Traceback (most recent call last):
  File "/home/airflow/.local/lib/python3.12/site-packages/airflow/models/taskinstance.py", line 465, in _execute_task
    result = _execute_callable(context=context, **execute_callable_kwargs)
             ^^^^^^^^^^^^^^^^^^^^^^^^^^^^^^^^^^^^^^^^^^^^^^^^^^^^^^^^^^^^^
  File "/home/airflow/.local/lib/python3.12/site-packages/airflow/models/taskinstance.py", line 432, in _execute_callable
    return execute_callable(context=context, **execute_callable_kwargs)
           ^^^^^^^^^^^^^^^^^^^^^^^^^^^^^^^^^^^^^^^^^^^^^^^^^^^^^^^^^^^^
  File "/home/airflow/.local/lib/python3.12/site-packages/airflow/models/baseoperator.py", line 401, in wrapper
    return func(self, *args, **kwargs)
           ^^^^^^^^^^^^^^^^^^^^^^^^^^^
  File "/home/airflow/.local/lib/python3.12/site-packages/airflow/operators/python.py", line 235, in execute
    return_value = self.execute_callable()
                   ^^^^^^^^^^^^^^^^^^^^^^^
  File "/home/airflow/.local/lib/python3.12/site-packages/airflow/operators/python.py", line 252, in execute_callable
    return self.python_callable(*self.op_args, **self.op_kwargs)
           ^^^^^^^^^^^^^^^^^^^^^^^^^^^^^^^^^^^^^^^^^^^^^^^^^^^^^
  File "/opt/airflow/scripts/predict.py", line 18, in predict_weather
    data['predicted_temperature_2m'] = model.predict(features)
                                       ^^^^^^^^^^^^^^^^^^^^^^^
  File "/home/airflow/.local/lib/python3.12/site-packages/sklearn/linear_model/_base.py", line 306, in predict
    return self._decision_function(X)
           ^^^^^^^^^^^^^^^^^^^^^^^^^^
  File "/home/airflow/.local/lib/python3.12/site-packages/sklearn/linear_model/_base.py", line 285, in _decision_function
    X = self._validate_data(X, accept_sparse=["csr", "csc", "coo"], reset=False)
        ^^^^^^^^^^^^^^^^^^^^^^^^^^^^^^^^^^^^^^^^^^^^^^^^^^^^^^^^^^^^^^^^^^^^^^^^
  File "/home/airflow/.local/lib/python3.12/site-packages/sklearn/base.py", line 608, in _validate_data
    self._check_feature_names(X, reset=reset)
  File "/home/airflow/.local/lib/python3.12/site-packages/sklearn/base.py", line 535, in _check_feature_names
    raise ValueError(message)
ValueError: The feature names should match those that were passed during fit.
Feature names unseen at fit time:
- date
Feature names seen at fit time, yet now missing:
- day
- hour
- month
- year

[2024-06-28T03:30:06.477+0000] {taskinstance.py:1206} INFO - Marking task as UP_FOR_RETRY. dag_id=weather_data_pipeline, task_id=predict_weather, run_id=scheduled__2024-06-27T00:00:00+00:00, execution_date=20240627T000000, start_date=20240628T033004, end_date=20240628T033006
[2024-06-28T03:30:06.498+0000] {standard_task_runner.py:110} ERROR - Failed to execute job 18 for task predict_weather (The feature names should match those that were passed during fit.
Feature names unseen at fit time:
- date
Feature names seen at fit time, yet now missing:
- day
- hour
- month
- year
; 588)
[2024-06-28T03:30:06.548+0000] {local_task_job_runner.py:240} INFO - Task exited with return code 1
[2024-06-28T03:30:06.573+0000] {taskinstance.py:3503} INFO - 0 downstream tasks scheduled from follow-on schedule check
[2024-06-28T03:30:06.576+0000] {local_task_job_runner.py:222} INFO - ::endgroup::
