[2024-06-28T10:38:39.117+0000] {local_task_job_runner.py:120} INFO - ::group::Pre task execution logs
[2024-06-28T10:38:39.136+0000] {taskinstance.py:2076} INFO - Dependencies all met for dep_context=non-requeueable deps ti=<TaskInstance: weather_data_pipeline.predict_weather manual__2024-06-28T10:33:25.506609+00:00 [queued]>
[2024-06-28T10:38:39.145+0000] {taskinstance.py:2076} INFO - Dependencies all met for dep_context=requeueable deps ti=<TaskInstance: weather_data_pipeline.predict_weather manual__2024-06-28T10:33:25.506609+00:00 [queued]>
[2024-06-28T10:38:39.145+0000] {taskinstance.py:2306} INFO - Starting attempt 2 of 2
[2024-06-28T10:38:39.160+0000] {taskinstance.py:2330} INFO - Executing <Task(PythonOperator): predict_weather> on 2024-06-28 10:33:25.506609+00:00
[2024-06-28T10:38:39.167+0000] {warnings.py:112} WARNING - /home/***/.local/lib/python3.12/site-packages/***/task/task_runner/standard_task_runner.py:61: DeprecationWarning: This process (pid=275) is multi-threaded, use of fork() may lead to deadlocks in the child.
  pid = os.fork()

[2024-06-28T10:38:39.169+0000] {standard_task_runner.py:90} INFO - Running: ['***', 'tasks', 'run', 'weather_data_pipeline', 'predict_weather', 'manual__2024-06-28T10:33:25.506609+00:00', '--job-id', '105', '--raw', '--subdir', 'DAGS_FOLDER/weather_dag.py', '--cfg-path', '/tmp/tmpe2k2g108']
[2024-06-28T10:38:39.169+0000] {standard_task_runner.py:63} INFO - Started process 296 to run task
[2024-06-28T10:38:39.170+0000] {standard_task_runner.py:91} INFO - Job 105: Subtask predict_weather
[2024-06-28T10:38:39.222+0000] {task_command.py:426} INFO - Running <TaskInstance: weather_data_pipeline.predict_weather manual__2024-06-28T10:33:25.506609+00:00 [running]> on host 361dbc9b179c
[2024-06-28T10:38:39.361+0000] {taskinstance.py:2648} INFO - Exporting env vars: AIRFLOW_CTX_DAG_OWNER='***' AIRFLOW_CTX_DAG_ID='weather_data_pipeline' AIRFLOW_CTX_TASK_ID='predict_weather' AIRFLOW_CTX_EXECUTION_DATE='2024-06-28T10:33:25.506609+00:00' AIRFLOW_CTX_TRY_NUMBER='2' AIRFLOW_CTX_DAG_RUN_ID='manual__2024-06-28T10:33:25.506609+00:00'
[2024-06-28T10:38:39.362+0000] {taskinstance.py:430} INFO - ::endgroup::
[2024-06-28T10:38:39.365+0000] {taskinstance.py:441} INFO - ::group::Post task execution logs
[2024-06-28T10:38:39.366+0000] {taskinstance.py:2905} ERROR - Task failed with exception
Traceback (most recent call last):
  File "/home/airflow/.local/lib/python3.12/site-packages/airflow/models/taskinstance.py", line 465, in _execute_task
    result = _execute_callable(context=context, **execute_callable_kwargs)
             ^^^^^^^^^^^^^^^^^^^^^^^^^^^^^^^^^^^^^^^^^^^^^^^^^^^^^^^^^^^^^
  File "/home/airflow/.local/lib/python3.12/site-packages/airflow/models/taskinstance.py", line 432, in _execute_callable
    return execute_callable(context=context, **execute_callable_kwargs)
           ^^^^^^^^^^^^^^^^^^^^^^^^^^^^^^^^^^^^^^^^^^^^^^^^^^^^^^^^^^^^
  File "/home/airflow/.local/lib/python3.12/site-packages/airflow/models/baseoperator.py", line 401, in wrapper
    return func(self, *args, **kwargs)
           ^^^^^^^^^^^^^^^^^^^^^^^^^^^
  File "/home/airflow/.local/lib/python3.12/site-packages/airflow/operators/python.py", line 235, in execute
    return_value = self.execute_callable()
                   ^^^^^^^^^^^^^^^^^^^^^^^
  File "/home/airflow/.local/lib/python3.12/site-packages/airflow/operators/python.py", line 252, in execute_callable
    return self.python_callable(*self.op_args, **self.op_kwargs)
           ^^^^^^^^^^^^^^^^^^^^^^^^^^^^^^^^^^^^^^^^^^^^^^^^^^^^^
  File "/opt/airflow/scripts/predict.py", line 7, in predict_weather
    data = pd.read_csv(file_path)
           ^^^^^^^^^^^^^^^^^^^^^^
  File "/home/airflow/.local/lib/python3.12/site-packages/pandas/io/parsers/readers.py", line 948, in read_csv
    return _read(filepath_or_buffer, kwds)
           ^^^^^^^^^^^^^^^^^^^^^^^^^^^^^^^
  File "/home/airflow/.local/lib/python3.12/site-packages/pandas/io/parsers/readers.py", line 611, in _read
    parser = TextFileReader(filepath_or_buffer, **kwds)
             ^^^^^^^^^^^^^^^^^^^^^^^^^^^^^^^^^^^^^^^^^^
  File "/home/airflow/.local/lib/python3.12/site-packages/pandas/io/parsers/readers.py", line 1448, in __init__
    self._engine = self._make_engine(f, self.engine)
                   ^^^^^^^^^^^^^^^^^^^^^^^^^^^^^^^^^
  File "/home/airflow/.local/lib/python3.12/site-packages/pandas/io/parsers/readers.py", line 1705, in _make_engine
    self.handles = get_handle(
                   ^^^^^^^^^^^
  File "/home/airflow/.local/lib/python3.12/site-packages/pandas/io/common.py", line 863, in get_handle
    handle = open(
             ^^^^^
OSError: [Errno 36] File name too long: '                        date  temperature_2m\n0  2024-06-26 00:00:00+00:00       18.108500\n1  2024-06-26 01:00:00+00:00       17.608500\n2  2024-06-26 02:00:00+00:00       17.158501\n3  2024-06-26 03:00:00+00:00       16.958500\n4  2024-06-26 04:00:00+00:00       17.708500\n5  2024-06-26 05:00:00+00:00       19.158501\n6  2024-06-26 06:00:00+00:00       20.658501\n7  2024-06-26 07:00:00+00:00       22.208500\n8  2024-06-26 08:00:00+00:00       24.008501\n9  2024-06-26 09:00:00+00:00       25.608500\n10 2024-06-26 10:00:00+00:00       26.758501\n11 2024-06-26 11:00:00+00:00       27.558500\n12 2024-06-26 12:00:00+00:00       28.458500\n13 2024-06-26 13:00:00+00:00       28.608500\n14 2024-06-26 14:00:00+00:00       28.708500\n15 2024-06-26 15:00:00+00:00       28.758501\n16 2024-06-26 16:00:00+00:00       28.658501\n17 2024-06-26 17:00:00+00:00       27.758501\n18 2024-06-26 18:00:00+00:00       26.458500\n19 2024-06-26 19:00:00+00:00       25.158501\n20 2024-06-26 20:00:00+00:00       24.358500\n21 2024-06-26 21:00:00+00:00       23.358500\n22 2024-06-26 22:00:00+00:00       22.358500\n23 2024-06-26 23:00:00+00:00       21.558500'
[2024-06-28T10:38:39.380+0000] {taskinstance.py:1206} INFO - Marking task as FAILED. dag_id=weather_data_pipeline, task_id=predict_weather, run_id=manual__2024-06-28T10:33:25.506609+00:00, execution_date=20240628T103325, start_date=20240628T103839, end_date=20240628T103839
[2024-06-28T10:38:39.392+0000] {standard_task_runner.py:110} ERROR - Failed to execute job 105 for task predict_weather ([Errno 36] File name too long: '                        date  temperature_2m\n0  2024-06-26 00:00:00+00:00       18.108500\n1  2024-06-26 01:00:00+00:00       17.608500\n2  2024-06-26 02:00:00+00:00       17.158501\n3  2024-06-26 03:00:00+00:00       16.958500\n4  2024-06-26 04:00:00+00:00       17.708500\n5  2024-06-26 05:00:00+00:00       19.158501\n6  2024-06-26 06:00:00+00:00       20.658501\n7  2024-06-26 07:00:00+00:00       22.208500\n8  2024-06-26 08:00:00+00:00       24.008501\n9  2024-06-26 09:00:00+00:00       25.608500\n10 2024-06-26 10:00:00+00:00       26.758501\n11 2024-06-26 11:00:00+00:00       27.558500\n12 2024-06-26 12:00:00+00:00       28.458500\n13 2024-06-26 13:00:00+00:00       28.608500\n14 2024-06-26 14:00:00+00:00       28.708500\n15 2024-06-26 15:00:00+00:00       28.758501\n16 2024-06-26 16:00:00+00:00       28.658501\n17 2024-06-26 17:00:00+00:00       27.758501\n18 2024-06-26 18:00:00+00:00       26.458500\n19 2024-06-26 19:00:00+00:00       25.158501\n20 2024-06-26 20:00:00+00:00       24.358500\n21 2024-06-26 21:00:00+00:00       23.358500\n22 2024-06-26 22:00:00+00:00       22.358500\n23 2024-06-26 23:00:00+00:00       21.558500'; 296)
[2024-06-28T10:38:39.426+0000] {local_task_job_runner.py:240} INFO - Task exited with return code 1
[2024-06-28T10:38:39.440+0000] {taskinstance.py:3503} INFO - 0 downstream tasks scheduled from follow-on schedule check
[2024-06-28T10:38:39.445+0000] {local_task_job_runner.py:222} INFO - ::endgroup::
