[2024-06-28T10:59:00.845+0000] {local_task_job_runner.py:120} INFO - ::group::Pre task execution logs
[2024-06-28T10:59:00.869+0000] {taskinstance.py:2076} INFO - Dependencies all met for dep_context=non-requeueable deps ti=<TaskInstance: weather_data_pipeline.fetch_weather_data manual__2024-06-28T10:53:55.027066+00:00 [queued]>
[2024-06-28T10:59:00.879+0000] {taskinstance.py:2076} INFO - Dependencies all met for dep_context=requeueable deps ti=<TaskInstance: weather_data_pipeline.fetch_weather_data manual__2024-06-28T10:53:55.027066+00:00 [queued]>
[2024-06-28T10:59:00.879+0000] {taskinstance.py:2306} INFO - Starting attempt 2 of 2
[2024-06-28T10:59:00.897+0000] {taskinstance.py:2330} INFO - Executing <Task(PythonOperator): fetch_weather_data> on 2024-06-28 10:53:55.027066+00:00
[2024-06-28T10:59:00.905+0000] {warnings.py:112} WARNING - /home/***/.local/lib/python3.12/site-packages/***/task/task_runner/standard_task_runner.py:61: DeprecationWarning: This process (pid=1454) is multi-threaded, use of fork() may lead to deadlocks in the child.
  pid = os.fork()

[2024-06-28T10:59:00.906+0000] {standard_task_runner.py:90} INFO - Running: ['***', 'tasks', 'run', 'weather_data_pipeline', 'fetch_weather_data', 'manual__2024-06-28T10:53:55.027066+00:00', '--job-id', '109', '--raw', '--subdir', 'DAGS_FOLDER/weather_dag.py', '--cfg-path', '/tmp/tmpd8j7hv8z']
[2024-06-28T10:59:00.907+0000] {standard_task_runner.py:63} INFO - Started process 1475 to run task
[2024-06-28T10:59:00.908+0000] {standard_task_runner.py:91} INFO - Job 109: Subtask fetch_weather_data
[2024-06-28T10:59:00.956+0000] {task_command.py:426} INFO - Running <TaskInstance: weather_data_pipeline.fetch_weather_data manual__2024-06-28T10:53:55.027066+00:00 [running]> on host 4200b9de651c
[2024-06-28T10:59:01.044+0000] {taskinstance.py:2648} INFO - Exporting env vars: AIRFLOW_CTX_DAG_OWNER='***' AIRFLOW_CTX_DAG_ID='weather_data_pipeline' AIRFLOW_CTX_TASK_ID='fetch_weather_data' AIRFLOW_CTX_EXECUTION_DATE='2024-06-28T10:53:55.027066+00:00' AIRFLOW_CTX_TRY_NUMBER='2' AIRFLOW_CTX_DAG_RUN_ID='manual__2024-06-28T10:53:55.027066+00:00'
[2024-06-28T10:59:01.046+0000] {taskinstance.py:430} INFO - ::endgroup::
[2024-06-28T10:59:01.061+0000] {taskinstance.py:441} INFO - ::group::Post task execution logs
[2024-06-28T10:59:01.062+0000] {taskinstance.py:2905} ERROR - Task failed with exception
Traceback (most recent call last):
  File "/home/airflow/.local/lib/python3.12/site-packages/airflow/models/taskinstance.py", line 465, in _execute_task
    result = _execute_callable(context=context, **execute_callable_kwargs)
             ^^^^^^^^^^^^^^^^^^^^^^^^^^^^^^^^^^^^^^^^^^^^^^^^^^^^^^^^^^^^^
  File "/home/airflow/.local/lib/python3.12/site-packages/airflow/models/taskinstance.py", line 432, in _execute_callable
    return execute_callable(context=context, **execute_callable_kwargs)
           ^^^^^^^^^^^^^^^^^^^^^^^^^^^^^^^^^^^^^^^^^^^^^^^^^^^^^^^^^^^^
  File "/home/airflow/.local/lib/python3.12/site-packages/airflow/models/baseoperator.py", line 401, in wrapper
    return func(self, *args, **kwargs)
           ^^^^^^^^^^^^^^^^^^^^^^^^^^^
  File "/home/airflow/.local/lib/python3.12/site-packages/airflow/operators/python.py", line 235, in execute
    return_value = self.execute_callable()
                   ^^^^^^^^^^^^^^^^^^^^^^^
  File "/home/airflow/.local/lib/python3.12/site-packages/airflow/operators/python.py", line 252, in execute_callable
    return self.python_callable(*self.op_args, **self.op_kwargs)
           ^^^^^^^^^^^^^^^^^^^^^^^^^^^^^^^^^^^^^^^^^^^^^^^^^^^^^
  File "/opt/airflow/scripts/fetch_weather_data.py", line 44, in fetch_weather_data
    return save_dataframe(hourly_dataframe, save_path)
           ^^^^^^^^^^^^^^^^^^^^^^^^^^^^^^^^^^^^^^^^^^^
  File "/opt/airflow/scripts/fetch_weather_data.py", line 48, in save_dataframe
    os.makedirs(os.path.dirname(save_path), exist_ok=True)
  File "<frozen os>", line 225, in makedirs
FileNotFoundError: [Errno 2] No such file or directory: ''
[2024-06-28T10:59:01.075+0000] {taskinstance.py:1206} INFO - Marking task as FAILED. dag_id=weather_data_pipeline, task_id=fetch_weather_data, run_id=manual__2024-06-28T10:53:55.027066+00:00, execution_date=20240628T105355, start_date=20240628T105900, end_date=20240628T105901
[2024-06-28T10:59:01.089+0000] {standard_task_runner.py:110} ERROR - Failed to execute job 109 for task fetch_weather_data ([Errno 2] No such file or directory: ''; 1475)
[2024-06-28T10:59:01.123+0000] {local_task_job_runner.py:240} INFO - Task exited with return code 1
[2024-06-28T10:59:01.145+0000] {taskinstance.py:3503} INFO - 0 downstream tasks scheduled from follow-on schedule check
[2024-06-28T10:59:01.153+0000] {local_task_job_runner.py:222} INFO - ::endgroup::
