[2024-06-28T10:53:58.077+0000] {local_task_job_runner.py:120} INFO - ::group::Pre task execution logs
[2024-06-28T10:53:58.105+0000] {taskinstance.py:2076} INFO - Dependencies all met for dep_context=non-requeueable deps ti=<TaskInstance: weather_data_pipeline.fetch_weather_data manual__2024-06-28T10:53:55.027066+00:00 [queued]>
[2024-06-28T10:53:58.115+0000] {taskinstance.py:2076} INFO - Dependencies all met for dep_context=requeueable deps ti=<TaskInstance: weather_data_pipeline.fetch_weather_data manual__2024-06-28T10:53:55.027066+00:00 [queued]>
[2024-06-28T10:53:58.115+0000] {taskinstance.py:2306} INFO - Starting attempt 1 of 2
[2024-06-28T10:53:58.131+0000] {taskinstance.py:2330} INFO - Executing <Task(PythonOperator): fetch_weather_data> on 2024-06-28 10:53:55.027066+00:00
[2024-06-28T10:53:58.138+0000] {warnings.py:112} WARNING - /home/***/.local/lib/python3.12/site-packages/***/task/task_runner/standard_task_runner.py:61: DeprecationWarning: This process (pid=1277) is multi-threaded, use of fork() may lead to deadlocks in the child.
  pid = os.fork()

[2024-06-28T10:53:58.141+0000] {standard_task_runner.py:63} INFO - Started process 1291 to run task
[2024-06-28T10:53:58.140+0000] {standard_task_runner.py:90} INFO - Running: ['***', 'tasks', 'run', 'weather_data_pipeline', 'fetch_weather_data', 'manual__2024-06-28T10:53:55.027066+00:00', '--job-id', '108', '--raw', '--subdir', 'DAGS_FOLDER/weather_dag.py', '--cfg-path', '/tmp/tmpmtvcv_lk']
[2024-06-28T10:53:58.142+0000] {standard_task_runner.py:91} INFO - Job 108: Subtask fetch_weather_data
[2024-06-28T10:53:58.191+0000] {task_command.py:426} INFO - Running <TaskInstance: weather_data_pipeline.fetch_weather_data manual__2024-06-28T10:53:55.027066+00:00 [running]> on host 4200b9de651c
[2024-06-28T10:53:58.287+0000] {taskinstance.py:2648} INFO - Exporting env vars: AIRFLOW_CTX_DAG_OWNER='***' AIRFLOW_CTX_DAG_ID='weather_data_pipeline' AIRFLOW_CTX_TASK_ID='fetch_weather_data' AIRFLOW_CTX_EXECUTION_DATE='2024-06-28T10:53:55.027066+00:00' AIRFLOW_CTX_TRY_NUMBER='1' AIRFLOW_CTX_DAG_RUN_ID='manual__2024-06-28T10:53:55.027066+00:00'
[2024-06-28T10:53:58.288+0000] {taskinstance.py:430} INFO - ::endgroup::
[2024-06-28T10:53:58.309+0000] {taskinstance.py:441} INFO - ::group::Post task execution logs
[2024-06-28T10:53:58.311+0000] {taskinstance.py:2905} ERROR - Task failed with exception
Traceback (most recent call last):
  File "/home/airflow/.local/lib/python3.12/site-packages/airflow/models/taskinstance.py", line 465, in _execute_task
    result = _execute_callable(context=context, **execute_callable_kwargs)
             ^^^^^^^^^^^^^^^^^^^^^^^^^^^^^^^^^^^^^^^^^^^^^^^^^^^^^^^^^^^^^
  File "/home/airflow/.local/lib/python3.12/site-packages/airflow/models/taskinstance.py", line 432, in _execute_callable
    return execute_callable(context=context, **execute_callable_kwargs)
           ^^^^^^^^^^^^^^^^^^^^^^^^^^^^^^^^^^^^^^^^^^^^^^^^^^^^^^^^^^^^
  File "/home/airflow/.local/lib/python3.12/site-packages/airflow/models/baseoperator.py", line 401, in wrapper
    return func(self, *args, **kwargs)
           ^^^^^^^^^^^^^^^^^^^^^^^^^^^
  File "/home/airflow/.local/lib/python3.12/site-packages/airflow/operators/python.py", line 235, in execute
    return_value = self.execute_callable()
                   ^^^^^^^^^^^^^^^^^^^^^^^
  File "/home/airflow/.local/lib/python3.12/site-packages/airflow/operators/python.py", line 252, in execute_callable
    return self.python_callable(*self.op_args, **self.op_kwargs)
           ^^^^^^^^^^^^^^^^^^^^^^^^^^^^^^^^^^^^^^^^^^^^^^^^^^^^^
  File "/opt/airflow/scripts/fetch_weather_data.py", line 44, in fetch_weather_data
    return save_dataframe(hourly_dataframe, save_path)
           ^^^^^^^^^^^^^^^^^^^^^^^^^^^^^^^^^^^^^^^^^^^
  File "/opt/airflow/scripts/fetch_weather_data.py", line 52, in save_dataframe
    os.remove(save_path)
IsADirectoryError: [Errno 21] Is a directory: './new_data.csv'
[2024-06-28T10:53:58.325+0000] {taskinstance.py:1206} INFO - Marking task as UP_FOR_RETRY. dag_id=weather_data_pipeline, task_id=fetch_weather_data, run_id=manual__2024-06-28T10:53:55.027066+00:00, execution_date=20240628T105355, start_date=20240628T105358, end_date=20240628T105358
[2024-06-28T10:53:58.338+0000] {standard_task_runner.py:110} ERROR - Failed to execute job 108 for task fetch_weather_data ([Errno 21] Is a directory: './new_data.csv'; 1291)
[2024-06-28T10:53:58.357+0000] {local_task_job_runner.py:240} INFO - Task exited with return code 1
[2024-06-28T10:53:58.380+0000] {taskinstance.py:3503} INFO - 0 downstream tasks scheduled from follow-on schedule check
[2024-06-28T10:53:58.384+0000] {local_task_job_runner.py:222} INFO - ::endgroup::
