[2024-06-28T08:27:29.410+0000] {local_task_job_runner.py:120} INFO - ::group::Pre task execution logs
[2024-06-28T08:27:29.543+0000] {taskinstance.py:2076} INFO - Dependencies all met for dep_context=non-requeueable deps ti=<TaskInstance: weather_data_pipeline.fetch_weather_data manual__2024-06-28T08:27:24.621647+00:00 [queued]>
[2024-06-28T08:27:29.552+0000] {taskinstance.py:2076} INFO - Dependencies all met for dep_context=requeueable deps ti=<TaskInstance: weather_data_pipeline.fetch_weather_data manual__2024-06-28T08:27:24.621647+00:00 [queued]>
[2024-06-28T08:27:29.553+0000] {taskinstance.py:2306} INFO - Starting attempt 1 of 2
[2024-06-28T08:27:29.568+0000] {taskinstance.py:2330} INFO - Executing <Task(PythonOperator): fetch_weather_data> on 2024-06-28 08:27:24.621647+00:00
[2024-06-28T08:27:29.575+0000] {warnings.py:112} WARNING - /home/***/.local/lib/python3.12/site-packages/***/task/task_runner/standard_task_runner.py:61: DeprecationWarning: This process (pid=87) is multi-threaded, use of fork() may lead to deadlocks in the child.
  pid = os.fork()

[2024-06-28T08:27:29.576+0000] {standard_task_runner.py:90} INFO - Running: ['***', 'tasks', 'run', 'weather_data_pipeline', 'fetch_weather_data', 'manual__2024-06-28T08:27:24.621647+00:00', '--job-id', '23', '--raw', '--subdir', 'DAGS_FOLDER/weather_dag.py', '--cfg-path', '/tmp/tmpvju8rcnq']
[2024-06-28T08:27:29.578+0000] {standard_task_runner.py:63} INFO - Started process 101 to run task
[2024-06-28T08:27:29.578+0000] {standard_task_runner.py:91} INFO - Job 23: Subtask fetch_weather_data
[2024-06-28T08:27:29.620+0000] {task_command.py:426} INFO - Running <TaskInstance: weather_data_pipeline.fetch_weather_data manual__2024-06-28T08:27:24.621647+00:00 [running]> on host 0c21145e706e
[2024-06-28T08:27:29.707+0000] {taskinstance.py:2648} INFO - Exporting env vars: AIRFLOW_CTX_DAG_OWNER='***' AIRFLOW_CTX_DAG_ID='weather_data_pipeline' AIRFLOW_CTX_TASK_ID='fetch_weather_data' AIRFLOW_CTX_EXECUTION_DATE='2024-06-28T08:27:24.621647+00:00' AIRFLOW_CTX_TRY_NUMBER='1' AIRFLOW_CTX_DAG_RUN_ID='manual__2024-06-28T08:27:24.621647+00:00'
[2024-06-28T08:27:29.708+0000] {taskinstance.py:430} INFO - ::endgroup::
[2024-06-28T08:27:29.921+0000] {taskinstance.py:441} INFO - ::group::Post task execution logs
[2024-06-28T08:27:29.921+0000] {taskinstance.py:2905} ERROR - Task failed with exception
Traceback (most recent call last):
  File "/home/airflow/.local/lib/python3.12/site-packages/airflow/models/taskinstance.py", line 465, in _execute_task
    result = _execute_callable(context=context, **execute_callable_kwargs)
             ^^^^^^^^^^^^^^^^^^^^^^^^^^^^^^^^^^^^^^^^^^^^^^^^^^^^^^^^^^^^^
  File "/home/airflow/.local/lib/python3.12/site-packages/airflow/models/taskinstance.py", line 432, in _execute_callable
    return execute_callable(context=context, **execute_callable_kwargs)
           ^^^^^^^^^^^^^^^^^^^^^^^^^^^^^^^^^^^^^^^^^^^^^^^^^^^^^^^^^^^^
  File "/home/airflow/.local/lib/python3.12/site-packages/airflow/models/baseoperator.py", line 401, in wrapper
    return func(self, *args, **kwargs)
           ^^^^^^^^^^^^^^^^^^^^^^^^^^^
  File "/home/airflow/.local/lib/python3.12/site-packages/airflow/operators/python.py", line 235, in execute
    return_value = self.execute_callable()
                   ^^^^^^^^^^^^^^^^^^^^^^^
  File "/home/airflow/.local/lib/python3.12/site-packages/airflow/operators/python.py", line 252, in execute_callable
    return self.python_callable(*self.op_args, **self.op_kwargs)
           ^^^^^^^^^^^^^^^^^^^^^^^^^^^^^^^^^^^^^^^^^^^^^^^^^^^^^
  File "/opt/airflow/dags/weather_dag.py", line 45, in fetch_weather_data_task
    combined_df, new_data = fetch_weather_data(city, df_path, save_path)
                            ^^^^^^^^^^^^^^^^^^^^^^^^^^^^^^^^^^^^^^^^^^^^
  File "/opt/airflow/scripts/fetch_weather_data.py", line 44, in fetch_weather_data
    return save_dataframe_to_csv(hourly_dataframe, city, save_path, df_path)
           ^^^^^^^^^^^^^^^^^^^^^^^^^^^^^^^^^^^^^^^^^^^^^^^^^^^^^^^^^^^^^^^^^
  File "/opt/airflow/scripts/fetch_weather_data.py", line 53, in save_dataframe_to_csv
    df.to_csv(existing_data_file, index=False)
  File "/home/airflow/.local/lib/python3.12/site-packages/pandas/core/generic.py", line 3902, in to_csv
    return DataFrameRenderer(formatter).to_csv(
           ^^^^^^^^^^^^^^^^^^^^^^^^^^^^^^^^^^^^
  File "/home/airflow/.local/lib/python3.12/site-packages/pandas/io/formats/format.py", line 1152, in to_csv
    csv_formatter.save()
  File "/home/airflow/.local/lib/python3.12/site-packages/pandas/io/formats/csvs.py", line 247, in save
    with get_handle(
         ^^^^^^^^^^^
  File "/home/airflow/.local/lib/python3.12/site-packages/pandas/io/common.py", line 739, in get_handle
    check_parent_directory(str(handle))
  File "/home/airflow/.local/lib/python3.12/site-packages/pandas/io/common.py", line 604, in check_parent_directory
    raise OSError(rf"Cannot save file into a non-existent directory: '{parent}'")
OSError: Cannot save file into a non-existent directory: 'paris_weather_data_4_years.csv'
[2024-06-28T08:27:29.940+0000] {taskinstance.py:1206} INFO - Marking task as UP_FOR_RETRY. dag_id=weather_data_pipeline, task_id=fetch_weather_data, run_id=manual__2024-06-28T08:27:24.621647+00:00, execution_date=20240628T082724, start_date=20240628T082729, end_date=20240628T082729
[2024-06-28T08:27:29.953+0000] {standard_task_runner.py:110} ERROR - Failed to execute job 23 for task fetch_weather_data (Cannot save file into a non-existent directory: 'paris_weather_data_4_years.csv'; 101)
[2024-06-28T08:27:29.993+0000] {local_task_job_runner.py:240} INFO - Task exited with return code 1
[2024-06-28T08:27:30.014+0000] {taskinstance.py:3503} INFO - 0 downstream tasks scheduled from follow-on schedule check
[2024-06-28T08:27:30.017+0000] {local_task_job_runner.py:222} INFO - ::endgroup::
